<?xml version="1.0" encoding="UTF-8"?>
<testng-results skipped="1" failed="1" ignored="0" total="4" passed="2">
  <reporter-output>
  </reporter-output>
  <suite name="Default suite" duration-ms="670" started-at="2017-11-06T04:00:15Z" finished-at="2017-11-06T04:00:16Z">
    <groups>
    </groups>
    <test name="Default test" duration-ms="670" started-at="2017-11-06T04:00:15Z" finished-at="2017-11-06T04:00:16Z">
      <class name="testbase.TC1">
        <test-method status="PASS" signature="M1()[pri:0, instance:testbase.TC1@d8355a8]" name="M1" is-config="true" duration-ms="246" started-at="2017-11-06T09:30:15Z" finished-at="2017-11-06T09:30:15Z">
          <reporter-output>
          </reporter-output>
        </test-method> <!-- M1 -->
        <test-method status="FAIL" signature="demoTestFail()[pri:0, instance:testbase.TC1@d8355a8]" name="demoTestFail" duration-ms="51" started-at="2017-11-06T09:30:15Z" finished-at="2017-11-06T09:30:16Z">
          <exception class="java.lang.AssertionError">
            <message>
              <![CDATA[expected [true] but found [false]]]>
            </message>
            <full-stacktrace>
              <![CDATA[java.lang.AssertionError: expected [true] but found [false]
	at org.testng.Assert.fail(Assert.java:93)
	at org.testng.Assert.failNotEquals(Assert.java:512)
	at org.testng.Assert.assertTrue(Assert.java:41)
	at org.testng.Assert.assertTrue(Assert.java:51)
	at testbase.TC1.demoTestFail(TC1.java:64)
	at sun.reflect.NativeMethodAccessorImpl.invoke0(Native Method)
	at sun.reflect.NativeMethodAccessorImpl.invoke(Unknown Source)
	at sun.reflect.DelegatingMethodAccessorImpl.invoke(Unknown Source)
	at java.lang.reflect.Method.invoke(Unknown Source)
	at org.testng.internal.MethodInvocationHelper.invokeMethod(MethodInvocationHelper.java:108)
	at org.testng.internal.Invoker.invokeMethod(Invoker.java:661)
	at org.testng.internal.Invoker.invokeTestMethod(Invoker.java:869)
	at org.testng.internal.Invoker.invokeTestMethods(Invoker.java:1193)
	at org.testng.internal.TestMethodWorker.invokeTestMethods(TestMethodWorker.java:126)
	at org.testng.internal.TestMethodWorker.run(TestMethodWorker.java:109)
	at org.testng.TestRunner.privateRun(TestRunner.java:744)
	at org.testng.TestRunner.run(TestRunner.java:602)
	at org.testng.SuiteRunner.runTest(SuiteRunner.java:380)
	at org.testng.SuiteRunner.runSequentially(SuiteRunner.java:375)
	at org.testng.SuiteRunner.privateRun(SuiteRunner.java:340)
	at org.testng.SuiteRunner.run(SuiteRunner.java:289)
	at org.testng.SuiteRunnerWorker.runSuite(SuiteRunnerWorker.java:52)
	at org.testng.SuiteRunnerWorker.run(SuiteRunnerWorker.java:86)
	at org.testng.TestNG.runSuitesSequentially(TestNG.java:1301)
	at org.testng.TestNG.runSuitesLocally(TestNG.java:1226)
	at org.testng.TestNG.runSuites(TestNG.java:1144)
	at org.testng.TestNG.run(TestNG.java:1115)
	at org.testng.remote.AbstractRemoteTestNG.run(AbstractRemoteTestNG.java:114)
	at org.testng.remote.RemoteTestNG.initAndRun(RemoteTestNG.java:251)
	at org.testng.remote.RemoteTestNG.main(RemoteTestNG.java:77)
]]>
            </full-stacktrace>
          </exception> <!-- java.lang.AssertionError -->
          <reporter-output>
          </reporter-output>
        </test-method> <!-- demoTestFail -->
        <test-method status="PASS" signature="demoTestPass()[pri:0, instance:testbase.TC1@d8355a8]" name="demoTestPass" duration-ms="4" started-at="2017-11-06T09:30:16Z" finished-at="2017-11-06T09:30:16Z">
          <reporter-output>
          </reporter-output>
        </test-method> <!-- demoTestPass -->
        <test-method status="SKIP" signature="demoTestSkip()[pri:0, instance:testbase.TC1@d8355a8]" name="demoTestSkip" duration-ms="2" started-at="2017-11-06T09:30:16Z" finished-at="2017-11-06T09:30:16Z">
          <exception class="org.testng.SkipException">
            <message>
              <![CDATA[This test case not ready for execution]]>
            </message>
            <full-stacktrace>
              <![CDATA[org.testng.SkipException: This test case not ready for execution
	at testbase.TC1.demoTestSkip(TC1.java:77)
	at sun.reflect.NativeMethodAccessorImpl.invoke0(Native Method)
	at sun.reflect.NativeMethodAccessorImpl.invoke(Unknown Source)
	at sun.reflect.DelegatingMethodAccessorImpl.invoke(Unknown Source)
	at java.lang.reflect.Method.invoke(Unknown Source)
	at org.testng.internal.MethodInvocationHelper.invokeMethod(MethodInvocationHelper.java:108)
	at org.testng.internal.Invoker.invokeMethod(Invoker.java:661)
	at org.testng.internal.Invoker.invokeTestMethod(Invoker.java:869)
	at org.testng.internal.Invoker.invokeTestMethods(Invoker.java:1193)
	at org.testng.internal.TestMethodWorker.invokeTestMethods(TestMethodWorker.java:126)
	at org.testng.internal.TestMethodWorker.run(TestMethodWorker.java:109)
	at org.testng.TestRunner.privateRun(TestRunner.java:744)
	at org.testng.TestRunner.run(TestRunner.java:602)
	at org.testng.SuiteRunner.runTest(SuiteRunner.java:380)
	at org.testng.SuiteRunner.runSequentially(SuiteRunner.java:375)
	at org.testng.SuiteRunner.privateRun(SuiteRunner.java:340)
	at org.testng.SuiteRunner.run(SuiteRunner.java:289)
	at org.testng.SuiteRunnerWorker.runSuite(SuiteRunnerWorker.java:52)
	at org.testng.SuiteRunnerWorker.run(SuiteRunnerWorker.java:86)
	at org.testng.TestNG.runSuitesSequentially(TestNG.java:1301)
	at org.testng.TestNG.runSuitesLocally(TestNG.java:1226)
	at org.testng.TestNG.runSuites(TestNG.java:1144)
	at org.testng.TestNG.run(TestNG.java:1115)
	at org.testng.remote.AbstractRemoteTestNG.run(AbstractRemoteTestNG.java:114)
	at org.testng.remote.RemoteTestNG.initAndRun(RemoteTestNG.java:251)
	at org.testng.remote.RemoteTestNG.main(RemoteTestNG.java:77)
]]>
            </full-stacktrace>
          </exception> <!-- org.testng.SkipException -->
          <reporter-output>
          </reporter-output>
        </test-method> <!-- demoTestSkip -->
        <test-method status="PASS" signature="checkFail()[pri:2, instance:testbase.TC1@d8355a8]" name="checkFail" duration-ms="2" started-at="2017-11-06T09:30:16Z" finished-at="2017-11-06T09:30:16Z">
          <reporter-output>
          </reporter-output>
        </test-method> <!-- checkFail -->
        <test-method status="PASS" signature="tear()[pri:0, instance:testbase.TC1@d8355a8]" name="tear" is-config="true" duration-ms="335" started-at="2017-11-06T09:30:16Z" finished-at="2017-11-06T09:30:16Z">
          <reporter-output>
          </reporter-output>
        </test-method> <!-- tear -->
      </class> <!-- testbase.TC1 -->
    </test> <!-- Default test -->
  </suite> <!-- Default suite -->
</testng-results>
